
代码可以抛出任何类型的异常，异常类是最有用的异常类型。实际上，异常类以层次结构编写，可以在捕获异常时使用多态。

\mySubsubsection{14.3.1}{C++标准异常的层次结构}

已经看到了C++标准异常层次结构中的几个异常：exception、runtime\_error 和 invalid\_argument。图14.3展示了完整的层次结构，展示了所有标准异常，包括在后续章节中讨论的标准库部分抛出的异常。

\myGraphic{0.9}{content/part3/chapter14/images/3.png}{图 14.3}

C++标准库抛出的异常都是这个层次结构中类的对象。层次结构中的每个类都支持一个what()成员函数，该函数返回一个描述异常的const char*字符串，可以在错误消息中使用这个字符串。

一些异常类需要在构造函数中设置由what()返回的字符串，这就是为什么在runtime\_error和invalid\_argument的构造函数中必须指定一个字符串。以下是另一个版本的readIntegerFile()，在错误消息中包含了文件名：

\begin{cpp}
vector<int> readIntegerFile(const string& filename)
{
    ifstream inputStream { filename };
    if (inputStream.fail()) {
        // We failed to open the file: throw an exception.
        const string error { format("Unable to open file {}.", filename) };
        throw invalid_argument { error };
    }

    // Read the integers one-by-one and add them to a vector.
    vector<int> integers;
    int temp;
    while (inputStream >> temp) {
        integers.push_back(temp);
    }

    if (!inputStream.eof()) {
        // We did not reach the end-of-file.
        // This means that some error occurred while reading the file.
        // Throw an exception.
        const string error { format("Unable to read file {}.", filename) };
        throw runtime_error { error };
    }

    return integers;
}
\end{cpp}

\mySubsubsection{14.3.2}{在类的层次结构中捕获异常}

异常层次结构的特性是，可以以多态方式捕获异常。以下两个catch语句，除了处理的异常类不同之外，其他都相同：

\begin{cpp}
try {
    myInts = readIntegerFile(filename);
} catch (const invalid_argument& e) {
    println(cerr, "{}", e.what());
    return 1;
} catch (const runtime_error& e) {
    println(cerr, "{}", e.what());
    return 1;
}
\end{cpp}

invalid\_argument和runtime\_error都是exception的派生类，可以用捕获exception的catch语句替换这两个catch语句：

\begin{cpp}
try {
    myInts = readIntegerFile(filename);
} catch (const exception& e) {
    println(cerr, "{}", e.what());
    return 1;
}
\end{cpp}

捕获异常引用的catch语句匹配exception的派生类，包括invalid\_argument和runtime\_error。请注意，在异常层次结构中捕获异常的位置越高，错误处理就越不具体。通常，应该尽可能在具体的层上捕获异常。

\begin{myWarning}{WARNING}
当以多态方式捕获异常时，确保通过引用捕获！如果通过值捕获异常，可能会遇到切片问题，在这种情况下会丢失对象的信息。有关切片的详细信息，请参阅第10章。
\end{myWarning}

使用多个catch子句时，catch子句会按照代码中出现的语法顺序进行匹配；第一个匹配的子句获胜。如果一个catch比后面的更具有包容性，将首先匹配，而后面的更具体的子句将不会执行。应该按照从最具体到最不具体的顺序排列catch子句。例如，想显式捕获readIntegerFile()抛出的invalid\_argument异常，但还想保留一个通用的异常处理程序来处理其他任何异常。正确的做法如下所示：

\begin{cpp}
try {
    myInts = readIntegerFile(filename);
} catch (const invalid_argument& e) { // List the derived class first.
    // Take some special action for invalid filenames.
} catch (const exception& e) { // Now list exception.
    println(cerr, "{}", e.what());
    return 1;
}
\end{cpp}

第一个catch语句捕获invalid\_argument异常，第二个捕获其他类型的exception异常。如果颠倒了catch子句的顺序，结果将不同：

\begin{cpp}
try {
    myInts = readIntegerFile(filename);
} catch (const exception& e) { // BUG: catching base class first!
    println(cerr, "{}", e.what());
    return 1;
} catch (const invalid_argument& e) {
    // Take some special action for invalid filenames.
}
\end{cpp}

这种情况下，从exception派生的类异常都会被第一个catch子句捕获；第二个catch将永远不会执行，有一些编译器会对这种情况发出警告。

\mySubsubsection{14.3.3}{编写异常类}

编写自己的异常类有两个优点：

\begin{itemize}
\item
C++标准库中的异常数量有限。可以创建具有更具体名称的类，而不是使用像runtime\_error这样的通用名称，以便更好地表示程序中的特定错误。

\item
可以向这些异常中添加自己的信息。标准层次结构中的大多数异常只允许设置一个错误字符串，而我们可能期望传递不同的信息。
\end{itemize}

建议自定义的所有异常类，都直接或间接地从标准异常类继承。如果项目中的每个人都遵循这个规则，那么可以知道程序中的每个异常都派生自exception（假设不使用违反这一规则的第三方库）。这个指导原则使得通过多态处理异常，变得更加简单。

来看一个例子。invalid\_argument和runtime\_error不能很好地捕捉readIntegerFile()中的文件打开和读取错误，可以为文件错误定义自己的错误层次结构，从通用的FileError类开始：

\begin{cpp}
class FileError : public exception
{
    public:
        explicit FileError(string filename) : m_filename { move(filename) } {}
        const char* what() const noexcept override { return m_message.c_str(); }
        virtual const string& getFilename() const noexcept { return m_filename; }
    protected:
        virtual void setMessage(string message) { m_message = move(message); }
    private:
        string m_filename;
        string m_message;
};
\end{cpp}

一个好的编程习惯是，使FileError成为标准异常层次结构的一部分，将其作为exception的子类似乎是合适的。从exception派生时，可以覆写what()成员函数，其原型如上所示。并且必须返回一个const char*字符串，该字符串在对象销毁之前有效FileError中，这个字符串来自m\_message数据成员。FileError的派生类可以使用受保护的setMessage()成员函数设置消息，通用的FileError类还包含一个文件名和该文件名的公共访问器。

readIntegerFile()中的第一个异常情况是文件无法打开，可能会创建一个从FileError派生的FileOpenError异常：

\begin{cpp}
class FileOpenError : public FileError
{
    public:
    explicit FileOpenError(string filename) : FileError { move(filename) }
    {
        setMessage(format("Unable to open {}.", getFilename()));
    }
};
\end{cpp}

FileOpenError异常调用setMessage()，将m\_message字符串更改为表示文件打开错误的字符串。构造函数体中，getFilename()用于获取文件名。不能使用filename参数，在调用FileError构造函数时，构造函数初始化器已经移动了filename。移动操作之后，就不应再使用该对象。

readIntegerFile()中的第二个异常情况是如果文件无法正确读取。对于这个异常，在从what()返回的错误消息字符串中，包含错误发生的行号，以及文件名可能很有用。这是一个从FileError派生的FileReadError异常：

\begin{cpp}
class FileReadError : public FileError
{
    public:
        explicit FileReadError(string filename, size_t lineNumber)
        : FileError { move(filename) }, m_lineNumber { lineNumber }
        {
            setMessage(format("Error reading {}, line {}.",
            getFilename(), lineNumber));
        }
        virtual size_t getLineNumber() const noexcept { return m_lineNumber; }
    private:
        size_t m_lineNumber { 0 };
};
\end{cpp}

为了正确设置行号，需要修改readIntegerFile()以跟踪读取的行数，而不仅仅是直接读取整数。这里是一个使用新异常的readIntegerFile()函数：

\begin{cpp}
vector<int> readIntegerFile(const string& filename)
{
    ifstream inputStream { filename };
    if (inputStream.fail()) {
        // We failed to open the file: throw an exception.
        throw FileOpenError { filename };
    }

    vector<int> integers;
    size_t lineNumber { 0 };
    while (!inputStream.eof()) {
        // Read one line from the file.
        string line;
        getline(inputStream, line);
        ++lineNumber;

        // Create a string stream out of the line.
        istringstream lineStream { line };
        // Read the integers one-by-one and add them to the vector.
        int temp;
        while (lineStream >> temp) {
            integers.push_back(temp);
        }

        if (!lineStream.eof()) {
            // We did not reach the end of the string stream.
            // This means that some error occurred while reading this line.
            // Throw an exception.
            throw FileReadError { filename, lineNumber };
        }
    }
    return integers;
}
\end{cpp}

调用readIntegerFile()的代码，使用多态来捕捉类型为FileError的异常：

\begin{cpp}
try {
    myInts = readIntegerFile(filename);
} catch (const FileError& e) {
    println(cerr, "{}", e.what());
    return 1;
}
\end{cpp}

自定义异常类时，有一个需要注意的问题。当一段代码抛出异常时，抛出的对象或值会通过移动构造函数或复制构造函数进行移动或复制，如果编写了一个其对象将作为异常抛出的类，必须确保这些对象是可复制的和/或可移动的。如果的异常类中有动态分配的内存，该类必须有一个析构函数，还必须有复制构造函数和复制赋值操作符和/或移动构造函数和移动赋值操作符，参见第9章。

\begin{myWarning}{WARNING}
作为异常抛出的对象，至少会移动或复制一次。
\end{myWarning}

异常可能会复制多次，但这只发生在按值捕获异常，而不是按引用捕获的情况下。

\begin{myNotic}{NOTE}
通过引用（最好是常量引用）捕获异常对象，以避免不必要的复制。
\end{myNotic}

\mySubsubsection{14.3.4}{嵌套异常}

有可能会发生这样的情况：处理第一个异常期间，触发了第二个异常情况，需要抛出第二个异常。不幸的是，当抛出第二个异常时，当前正在尝试处理的第一个异常的所有信息都将丢失。C++为这个问题提供的解决方案称为嵌套异常，允许在新异常的上下文中嵌套一个捕获的异常。如果调用一个第三方库的函数，该函数抛出一个类型为A的异常，但只想在代码中使用类型为B的异常，捕获库中的所有异常，并将它们嵌套在类型为B的异常中。

使用std::throw\_with\_nested()来抛出一个内部嵌套了另一个异常的异常，这个新异常的捕获处理器可以使用dynamic\_cast()，来获取代表第一个异常的std::nested\_exception的访问权限。接下来的示例，首先定义了一个MyException类，该类从exception派生并在其构造函数中接受一个字符串：

\begin{cpp}
class MyException : public exception
{
    public:
        explicit MyException(string message) : m_message { move(message) } {}
        const char* what() const noexcept override { return m_message.c_str(); }
    private:
        string m_message;
};
\end{cpp}

接下来的doSomething()函数抛出一个runtime\_error，该异常立即捕获并处理。捕获处理器写入一条消息，然后使用throw\_with\_nested()函数抛出一个第二个异常，第一个异常嵌套在其中。注意，嵌套异常是自动发生的：

\begin{cpp}
void doSomething()
{
    try {
        throw runtime_error { "A runtime_error exception" };
    } catch (const runtime_error& e) {
        println("doSomething() caught a runtime_error");
        println("doSomething() throwing MyException");
        throw_with_nested(
            MyException { "MyException with nested runtime_error" });
    }
}
\end{cpp}

throw\_with\_nested()通过抛出一个未命名、编译器生成的新类型来实现，该类型同时派生自nested\_exception和（这个例子中）MyException。这是C++中多重继承的一个示例，nested\_exception基类的默认构造函数通过调用std::current\_exception()自动捕获当前正在处理的异常，并将其存储在std::exception\_ptr中。exception\_ptr是一种指针样类型，能够存储空指针或指向使用current\_exception()捕获并抛出的异常对象的指针。exception\_ptr的实例可以传递给函数（通常是通过值），并在不同的线程之间传递。

以下代码片段演示了，如何处理带有嵌套异常的异常。代码调用doSomething()，并且有一个用于捕获类型为MyException的异常的捕获处理。捕获这样的异常时，写入一条消息，然后使用dynamic\_cast()获取嵌套异常的访问权限。如果没有嵌套异常，结果将是一个空指针。如果内部有嵌套异常，则在nested\_exception上调用rethrow\_nested()成员函数。这导致嵌套异常会重新抛出，然后可以在另一个try/catch块中再次捕获。

\begin{cpp}
try {
    doSomething();
} catch (const MyException& e) {
    println("main() caught MyException: {}", e.what());

    const auto* nested { dynamic_cast<const nested_exception*>(&e) };
    if (nested) {
        try {
            nested->rethrow_nested();
        } catch (const runtime_error& e) {
            // Handle nested exception.
            println(" Nested exception: {}", e.what());
        }
    }
}
\end{cpp}

输出如下：

\begin{shell}
doSomething() caught a runtime_error
doSomething() throwing MyException
main() caught MyException: MyException with nested runtime_error
  Nested exception: A runtime_error exception
\end{shell}


这段代码使用dynamic\_cast()来检查是否有嵌套异常。因为想检查嵌套异常，必须执行dynamic\_cast()，所以标准提供了一个名为std::rethrow\_if\_nested()的辅助函数来完成这个操作。这个辅助函数的用法：

\begin{cpp}
try {
    doSomething();
} catch (const MyException& e) {
    println("main() caught MyException: {}", e.what());
    try {
        rethrow_if_nested(e);
    } catch (const runtime_error& e) {
        // Handle nested exception.
        println(" Nested exception: {}", e.what());
    }
}
\end{cpp}

throw\_with\_nested()、nested\_exception、rethrow\_if\_nested()、current\_exception()和exception\_ptr都定义在<exception>中。







